Workbook
Name Display_Week: 'Project Schedule Phase 1 Old'!$J$4
Name Display_Week: [1]ProjectSchedule!$E$4
Name PlannedEnd: 'Project Schedule Phase 1 Old'!$J1
Name PlannedEnd: #REF!
Name PlannedStart: 'Project Schedule Phase 1 Old'!$I1
Name PlannedStart: #REF!
Name Project_Start: 'Project Schedule Phase 1 Old'!$J$3
Name Project_Start: [1]ProjectSchedule!$E$3
Name task_end: 'Project Schedule Phase 1 Old'!$L1
Name task_progress: 'Project Schedule Phase 1 Old'!$H1
Name task_start: 'Project Schedule Phase 1 Old'!$K1
Name today: TODAY()

Sheet ADK Wholesale Order Form P1
A1: Show: _________________________ | C1: Order Date: ______ | H1: Ship Date: _______ | I1: Contact Name: ______________ | O1: Phone: _________________________ | P1: Email: _________________________
A2: Store / Company Name:_____________________________ | H2: Resale #: _________ | I2: New Customer or Reorder: ___________________________________________ | O2: Total Order Amount: ___________________________
A3: Shipping Address:_____________________________ | H3: State: ___________ | I3: Country:_____________ | O3: Subtotal Amount: _____________________________________
A4: Card #:____________________________________________ | H4: CVC: ___________ | I4: Cardholder Name: _______________ | O4: Shipping (7% of Subtotal): ______________________________
A5: 100% All-Natural Soy Candles | H5: Floral/Earthy Candles | I5: SKU | J5: SRP | K5: Unit | L5: Qty | M5: Total | O5: Gift Sets, Perfume, Room Spray and Diffuser
A6: Best Selling Balsam Candles | B6: SKU | C6: SRP | D6: Unit | E6: Qty | F6: Total | H6: Sweetgrass Candle 4.5oz | I6: FA1004001-4.5 | J6: 22 | K6: =J6/2 -> 11 | O6: Gift Sets | P6: SKU | Q6: SRP | R6: Unit | S6: Qty | T6: Total
A7: Balsam & Cedar Candle 4.5oz | B7: FA1001001-4.5 | C7: 22 | D7: =C7/2 -> 11 | H7: Sweetgrass Candle 10oz | I7: FA1004002-10 | J7: 43 | K7: =J7/2 -> 21.5 | O7: ADK Candle Discovery Set 4.5oz x 3 | P7: FA7000001-4.5 | Q7: 68 | R7: =Q7/2 -> 34
A8: Balsam & Cedar Candle 10oz | B8: FA1001002-10 | C8: 43 | D8: =C8/2 -> 21.5 | H8: Sweetgrass Candle 20oz | I8: FA1004004-20 | J8: 66 | K8: =J8/2 -> 33 | O8: Holiday Candle Gift Set 10oz*3 | P8: FA7000003-10 | Q8: 126 | R8: =Q8/2 -> 63
A9: Balsam & Cedar Candle 20oz | B9: FA1001004-20 | C9: 66 | D9: =C9/2 -> 33 | H9: Lily of The Valley Candle 4.5oz | I9: FA1020001-4.5 | J9: 22 | K9: =J9/2 -> 11 | O9: 6 Handmade 4oz Soap Gift Set | P9: FA7000007-4B | Q9: 68 | R9: =Q9/2 -> 34
A10: Balsam & Lavender Candle 4.5oz | B10: FA1002001-4.5 | C10: 22 | D10: =C10/2 -> 11 | H10: Lily of The Valley Candle 10oz | I10: FA1020002-10 | J10: 43 | K10: =J10/2 -> 21.5 | O10: Four Seasons Gift Set | P10: FA7000006-2.7 | Q10: 49 | R10: =Q10/2 -> 24.5
A11: Balsam & Lavender Candle 10oz | B11: FA1002003-10 | C11: 43 | D11: =C11/2 -> 21.5 | H11: Lily of The Valley Candle 20oz | I11: FA1020003-20 | J11: 66 | K11: 33 | O11: Balsam & Green Tea 4.5oz Teapot Candle Gift Set | P11: FP7052001-4.5 | Q11: 45 | R11: 22.5
A12: Balsam & Lavender Candle 20oz | B12: FA1002006-20 | C12: 66 | D12: =C12/2 -> 33 | H12: Milkweed Candle 4.5oz | I12: FA103001-4.5 | J12: 22 | K12: =J12/2 -> 11 | O12: ADK Candle Care Kit & Dual 4.5 oz Candle Gift Set | P12: FA7000010 | Q12: 79 | R12: 39.5
A13: Balsam Fir Candle 4.5oz | B13: FA1003001-4.5 | C13: 22 | D13: =C13/2 -> 11 | H13: Milkweed Candle 10oz | I13: FA1030002-10 | J13: 43 | K13: =J13/2 -> 21.5 | O13: Artisan Perfume | P13: SKU | Q13: SRP | R13: Unit | S13: Qty | T13: Total
A14: Balsam Fir Candle 10oz | B14: FA1003002-10 | C14: 43 | D14: =C14/2 -> 21.5 | H14: Milkweed Candle 20oz | I14: FA1030003-20 | J14: 66 | K14: =J14/2 -> 33 | O14: Artisan Perfume Spray Discovery Set .07oz x 5 | P14: FA3000001-0.07 | Q14: 34 | R14: =Q14/2 -> 17
A15: Balsam Fir Candle 20oz | B15: FA1003004-20 | C15: 66 | D15: =C15/2 -> 33 | H15: Wild Rose Candle 4.5oz | I15: FA1021001-4.5 | J15: 22 | K15: =J15/2 -> 11 | O15: Botanical Perfume Spray Discovery Set .07oz x 5 | P15: FA3000006-.07 x 5 | Q15: 34 | R15: 17
A16: Candles with a Gift Box | B16: SKU | C16: SRP | D16: Unit | E16: Qty | F16: Total | H16: Wild Rose Candle 10oz | I16: FA1021002-10 | J16: 43 | K16: =J16/2 -> 21.5 | O16: Forest Serenity Perfume Spray Discovery Set .07ozx5 | P16: FA3000010-.07x5 | Q16: 34 | R16: 17
A17: Lavender Balsam Candle 4.5oz | B17: FA1002002-4.5B | C17: 22 | D17: =C17/2 -> 11 | H17: Wild Rose Candle 20oz | I17: FA1021003-20 | J17: 66 | K17: 33 | O17: Balsam & Cedar Artisan Perfume Spray 1oz | P17: FA3001001-1 | Q17: 57 | R17: =Q17/2 -> 28.5
A18: Lavender Balsam Candle 10 oz | B18: FA1002004-10B | C18: 43 | D18: =C18/2 -> 21.5 | H18: Fennel Mint Candle 4.5oz | I18: FA1022001-4.5 | J18: 22 | K18: =J18/2 -> 11 | O18: Balsam & Cedar Artisan Perfume Roller 0.33oz | P18: FA3001006-.33 | Q18: 29 | R18: 14.5
A19: Lavender Balsam Candle 20 oz | B19: FA1002007-20B | C19: 66 | D19: =C19/2 -> 33 | H19: Fennel Mint Candle 10oz | I19: FA1022001-10 | J19: 43 | K19: =J19/2 -> 21.5 | O19: Balsam & Lavender Artisan Perfume Spray 1oz | P19: FA3002001-1 | Q19: 57 | R19: =Q19/2 -> 28.5
A20: Mountain Air Candle 4.5oz | B20: FA1016001-4.5B | C20: 22 | D20: =C20/2 -> 11 | H20: Fennel Mint Candle 20oz | I20: FA1022002-20 | J20: 66 | K20: =J20/2 -> 33 | O20: Balsam & Lavender Artisan Perfume Roller 0.33oz | P20: FA3002006-.33 | Q20: 29 | R20: 14.5
A21: Mountain Air Candle 10oz | B21: FA1016002-10B | C21: 43 | D21: =C21/2 -> 21.5 | H21: Forget-Me-Not 4.5oz | I21: FA1019001-4.5 | J21: 22 | K21: =J21/2 -> 11 | O21: Sweetgrass Artisan Perfume Spray 1oz | P21: FA3004001-1 | Q21: 57 | R21: =Q21/2 -> 28.5
A22: Mountain Air Candle 20oz | B22: FA1016003-20B | C22: 66 | D22: =C22/2 -> 33 | H22: Forget-Me-Not 10oz | I22: FA1019002-10 | J22: 43 | K22: =J22/2 -> 21.5 | O22: Sweetgrass Artisan Perfume Roller 0.33oz | P22: FA3004004-.33 | Q22: 29 | R22: 14.5
A23: Lilac Candle 4.5oz | B23: FA1015001-4.5B | C23: 22 | D23: =C23/2 -> 11 | H23: Forget-Me-Not 20oz | I23: FA1019003-20 | J23: 66 | K23: 33 | O23: Lilac Botanical Perfume Spray 1oz | P23: FA3015001-1 | Q23: 49 | R23: =Q23/2 -> 24.5
A24: Lilac Candle 10oz | B24: FA1015002-10B | C24: 43 | D24: =C24/2 -> 21.5 | H24: Maple Candles | I24: SKU | J24: SRP | K24: Unit | L24: Qty | M24: Total | O24: Lilac Botanical Perfume Roller 0.33oz | P24: FA3015006-0.33 | Q24: 29 | R24: 14.5
A25: Lilac Candle 20oz | B25: FA1015003-20B | C25: 66 | D25: =C25/2 -> 33 | H25: Maple Bourbon Candle 4.5oz | I25: FA1026001-4.5 | J25: 22 | K25: =J25/2 -> 11 | O25: Wild Rose Artisan Perfume Spray 1oz | P25: FA3021001-1 | Q25: 57 | R25: =Q25/2 -> 28.5
A26: Shinrin Yoku Candle 4.5oz | B26: FA1017001-4.5B | C26: 22 | D26: =C26/2 -> 11 | H26: Maple Bourbon Candle 10oz | I26: FA1026002-10 | J26: 43 | K26: 21.5 | O26: Wild Rose Artisan Perfume Roller 0.33oz | P26: FA3021004-.33 | Q26: 29 | R26: 14.5
A27: Shinrin Yoku Candle 10oz | B27: FA1017001-10B | C27: 43 | D27: =C27/2 -> 21.5 | H27: Maple Bourbon Candle 20oz | I27: FA1026004-20 | J27: 66 | K27: =J27/2 -> 33 | O27: Milkweed Flower Artisan Perfume Spray 1oz | P27: FA3030001-1 | Q27: 57 | R27: =Q27/2 -> 28.5
A28: Shinrin Yoku Candle 20oz | B28: FA1017002-20B | C28: 66 | D28: =C28/2 -> 33 | H28: Maple Cinnamon Candle 4.5oz | I28: FA1027001-4.5 | J28: 22 | K28: =J28/2 -> 11 | O28: Milkweed Flower Artisan Perfume Roller 0.33oz | P28: FA3030004-.33 | Q28: 29 | R28: 14.5
A29: Seasonal Candles | B29: SKU | C29: SRP | D29: Unit | E29: Qty | F29: Total | H29: Maple Cinnamon Candle 10oz | I29: FA1027002-10 | J29: 43 | K29: 21.5 | O29: Vanilla Balsam Botanical Perfume Spray 1oz | P29: FA3035001-1 | Q29: 57 | R29: =Q29/2 -> 28.5
A30: Winterberry Candle 4.5oz | B30: FA1034001-4.5 | C30: 22 | D30: =C30/2 -> 11 | H30: Maple Cinnamon Candle 20oz | I30: FA1027004-20 | J30: 66 | K30: =J30/2 -> 33 | O30: Vanilla Balsam Botanical Perfume Roller 0.33oz | P30: FA3035004-0.33 | Q30: 29 | R30: 14.5
A31: Winterberry Candle 10oz | B31: FA1034002-10 | C31: 43 | D31: =C31/2 -> 21.5 | H31: Maple Vanilla Candle 4.5oz | I31: FA1028001-4.5 | J31: 22 | K31: =J31/2 -> 11 | O31: Berries & Roses Botanical Perfume Spray 1oz | P31: FA3069001-1 | Q31: 57 | R31: =Q31/2 -> 28.5
A32: Winterberry Candle 20oz | B32: FA1034005-20 | C32: 66 | D32: =C32/2 -> 33 | H32: Maple Vanilla Candle 10oz | I32: FA1028002-10 | J32: 43 | K32: 21.5 | O32: Berries & Roses Botanical Perfume Roller 0.33oz | P32: FA3069004-0.33 | Q32: 29 | R32: 14.5
A33: Sugar Cookie Candle 4.5oz | B33: FA1033001-4.5 | C33: 22 | D33: =C33/2 -> 11 | H33: Maple Vanilla Candle 20oz | I33: FA1028004-20 | J33: 66 | K33: =J33/2 -> 33 | O33: Patchouli Orange Botanical Perfume Spray 1oz | P33: FA3070001-1 | Q33: 49 | R33: =Q33/2 -> 24.5
A34: Sugar Cookie Candle 10oz | B34: FA1033002-10 | C34: 43 | D34: =C34/2 -> 21.5 | H34: Room Spray | I34: SKU | J34: SRP | K34: Unit | L34: Qty | M34: Total | O34: Patchouli Orange Botanical Perfume Roller 0.33oz | P34: FA3070003-0.33 | Q34: 29 | R34: 14.5
A35: Sugar Cookie Candle 20oz | B35: FA1033002-20 | C35: 66 | D35: =C35/2 -> 33 | H35: Balsam & Cedar 3.4oz | I35: FA3001002-3.4 | J35: 34 | K35: =J35/2 -> 17 | O35: Marigold & Chamomile Botanical Perfume Spray 1oz | P35: FA3071001-1 | Q35: 57 | R35: =Q35/2 -> 28.5
A36: Pumpkin Spice Candle 4.5oz | B36: FA1000004-4.5 | C36: 22 | D36: =C36/2 -> 11 | H36: Balsam & Lavender 3.4oz | I36: FA3002002-3.4 | J36: 34 | K36: =J36/2 -> 17 | O36: Marigold & Chamomile Botanical Perfume Roller 0.33oz | P36: FA3071003-0.33 | Q36: 29 | R36: 14.5
A37: Pumpkin Spice Candle 10oz | B37: FA1000005-10 | C37: 43 | D37: =C37/2 -> 21.5 | H37: Lilac 3.4oz | I37: FA3015002-3.4 | J37: 34 | K37: =J37/2 -> 17 | O37: Balsam Fir Forest Serenity Perfume Spray 1oz | P37: FA3003004-1 | Q37: 57 | R37: =Q37/2 -> 28.5
A38: Pumpkin Spice Candle 20oz | B38: FA1000009-20 | C38: 66 | D38: =C38/2 -> 33 | H38: Mountain Air 3.4oz | I38: FA3016002-3.4 | J38: 34 | K38: =J38/2 -> 17 | O38: Balsam Fir Forest Serenity Perfume Roller .33 oz | P38: FA3003005-.33 | Q38: 29 | R38: 14.5
A39: Apple Cinnamon Candle 4.5oz | B39: FA1000002-4.5 | C39: 22 | D39: =C39/2 -> 11 | H39: Reed Diffuser | I39: SKU | J39: SRP | K39: Unit | L39: Qty | M39: Total | O39: Birch Forest Serenity Perfume Spray 1oz | P39: FA3073002-1 | Q39: 57 | R39: =Q39/2 -> 28.5
A40: Apple Cinnamon Candle 10oz | B40: FA1000003-10 | C40: 43 | D40: =C40/2 -> 21.5 | H40: Lavender Balsam Diffuser 4oz | I40: FA3002005-4 | J40: 34 | K40: =J40/2 -> 17 | O40: Birch Forest Serenity Perfume Roller .33 oz | P40: FA3073003-.33 | Q40: 29 | R40: 14.5
...

Sheet ADK Wholesale Order Form P2
A1: All Natural Handmade Soap | B1: SKU | C1: SRP | D1: Unit | E1: Qty | F1: Total | H1: All Natural Handmade Soap | I1: SKU | J1: SRP | K1: Unit | L1: Qty | M1: Total | O1: Outdoor | P1: SKU | Q1: SRP | R1: Unit | S1: Qty | T1: Total
A2: Balsam Unwrapped Soap Bar 1oz | B2: FA2003002-1U | C2: 4 | D2: =C2/2 -> 2 | H2: Goat Milk Unwrapped Soap Bar 1oz | I2: FA2008001-1U | J2: 4 | K2: =J2/2 -> 2 | O2: Bug Repellent Spray 2oz | P2: FA8000001-2 | Q2: 16 | R2: 8
A3: Balsam Cloth Wrapped Soap Bar 2oz | B3: FA2003001-2W | C3: 8 | D3: 3.5 | H3: Goat Milk Unwrapped Soap Bar 4oz | I3: FA2008002-4U | J3: 10 | K3: =J3/2 -> 5 | O3: Bug Repellent Spray 4oz | P3: FA8000002-4 | Q3: 25 | R3: 12.5
A4: Balsam Unwrapped Soap Bar 4oz | B4: FA2003003-4U | C4: 10 | D4: =C4/2 -> 5 | H4: Goat Milk Wrapped Soap Bar 4oz | I4: FA2008003-4W | J4: 11 | K4: =J4/2 -> 5.5 | O4: Bug Bite Soother Roll-on | P4: FA8000003-0.33 | Q4: 10 | R4: 5
A5: Balsam Wrapped Soap Bar 4oz | B5: FA2003004-4W | C5: 11 | D5: =C5/2 -> 5.5 | H5: Goat Milk Boxed Soap Bar 16oz | I5: FA2008004-16B | J5: 37 | K5: =J5/2 -> 18.5 | O5: Bug Balm 2oz | P5: FA8000004-2 | Q5: 23 | R5: 11.5
A6: Balsam Labeled Boxed Soap Bar 16oz | B6: FA2003005-16B | C6: 37 | D6: =C6/2 -> 18.5 | H6: Goat Milk Unwrapped Soap Bar 24oz | I6: FA2008005-24U | J6: 52 | K6: =J6/2 -> 26 | O6: Bug Wipes 18 Count | P6: FA8000005-18 | Q6: 14 | R6: 7
A7: Balsam Unwrapped Soap Bar 24oz | B7: FA2003006-24U | C7: 52 | D7: =C7/2 -> 26 | H7: Patchouli Unwrapped Soap Bar 1oz | I7: FA2014001-1U | J7: 4 | K7: =J7/2 -> 2 | O7: Bug Wipes 30 Count | P7: FA8000006-30 | Q7: 20 | R7: =Q7/2 -> 10
A8: Cedar Unwrapped Soap Bar 1oz | B8: FA2006001-1U | C8: 4 | D8: =C8/2 -> 2 | H8: Patchouli Unwrapped Soap Bar 4oz | I8: FA2014002-4U | J8: 10 | K8: =J8/2 -> 5 | O8: Bug Repellent Tin Candle 1.3oz | P8: FA8000007-1.3 | Q8: 14 | R8: =Q8/2 -> 7
A9: Cedar Unwrapped Soap Bar 4oz | B9: FA2006002-4U | C9: 10 | D9: =C9/2 -> 5 | H9: Patchouli Wrapped Soap Bar 4oz | I9: FA2014003-4W | J9: 11 | K9: =J9/2 -> 5.5
A10: Cedar Wrapped Soap Bar 4oz | B10: FA2006003-4W | C10: 11 | D10: =C10/2 -> 5.5 | H10: Patchouli Boxed Soap Bar 16oz | I10: FA2014004-16B | J10: 37 | K10: =J10/2 -> 18.5
A11: Cedar Boxed Soap Bar 16oz | B11: FA2006004-16B | C11: 37 | D11: =C11/2 -> 18.5 | H11: Patchouli Unwrapped Soap Bar 24oz | I11: FA2014005-24U | J11: 52 | K11: =J11/2 -> 26 | O11: Bug Repellent Glass Candle 4.5oz | P11: FA8000008-4.5 | Q11: 22 | R11: =Q11/2 -> 11
A12: Cedar Unwrapped Soap Bar 24oz | B12: FA2006005-24U | C12: 52 | D12: =C12/2 -> 26 | H12: Ginger Bread Soap Bar Cloth Wrapped 2oz | I12: FA2013004-2W | J12: 8 | K12: 4
A13: Birch Unwrapped Soap Bar 1oz | B13: FA2005001-1U | C13: 4 | D13: =C13/2 -> 2 | H13: Sugar Cookie Soap Bar Cloth Wrapped 2oz | I13: FA2008006-2W | J13: 8 | K13: 4
A14: Birch Unwrapped Soap Bar 4oz | B14: FA2005002-4U | C14: 10 | D14: =C14/2 -> 5 | H14: Balsam Cedar Soap Bar Cloth Wrapped 2oz | I14: FA2001001-2W | J14: 8 | K14: 4 | O14: Bug Repellent Glass Candle 10oz | P14: FA8000009-10 | Q14: 43 | R14: =Q14/2 -> 21.5
A15: Birch Wrapped Soap Bar 4oz | B15: FA2005003-4W | C15: 11 | D15: =C15/2 -> 5.5 | H15: Winterberry Soap Bar Cloth Wrapped 2oz | I15: FA2007001-2W | J15: 8 | K15: 4
A16: Birch Boxed Soap Bar 16oz | B16: FA2005004-16B | C16: 37 | D16: =C16/2 -> 18.5 | H16: Cloth Wrapped Soap Bar Set of 6 x 2oz | I16: FA7000002-12W | J16: 41 | K16: 20.5
A17: Birch Unwrapped Soap Bar 24oz | B17: FA2005005-24U | C17: 52 | D17: =C17/2 -> 26 | H17: Deluxe Soap Bars | I17: SKU | J17: SRP | K17: Unit | L17: Qty | M17: Total | O17: Bug Repellent Soap 3oz | P17: FA8000010-3W | Q17: 10 | R17: 5
A18: Balsam & Lavender Unwrapped Soap Bar 1oz | B18: FA2002001-1U | C18: 4 | D18: =C18/2 -> 2 | H18: Mountain Air Wrapped Soap Bar 4oz | I18: FA2016002-4W | J18: 11 | K18: =J18/2 -> 5.5 | O18: Fisherman's Wrapped Soap Bar 4oz | P18: FA2000003-4W | Q18: 11 | R18: =Q18/2 -> 5.5
A19: Balsam & Lavender Cloth Wrapped Soap Bar 2oz | B19: FA2002002-2W | C19: 8 | D19: 3.5 | H19: Lavender Balsam Wrapped Soap Bar 4oz | I19: FA2002007-4W | J19: 11 | K19: =J19/2 -> 5.5
A20: Balsam & Lavender Unwrapped Soap Bar 4oz | B20: FA2002003-4U | C20: 10 | D20: 4.25 | H20: Lilac Wrapped Soap Bar 4oz | I20: FA2015002-4W | J20: 11 | K20: =J20/2 -> 5.5
A21: Balsam & Lavender Wrapped Soap Bar 4oz | B21: FA2002004-4W | C21: 11 | D21: =C21/2 -> 5.5 | H21: Shinrin-Yoku Wrapped Soap Bar 4oz | I21: FA2017002-4W | J21: 11 | K21: =J21/2 -> 5.5 | O21: Worker's Wrapped Soap Bar 4oz | P21: FA2000004-4W | Q21: 11 | R21: =Q21/2 -> 5.5
A22: Balsam & Lavender Boxed Soap Bar 16oz | B22: FA2002005-16B | C22: 37 | D22: =C22/2 -> 18.5 | H22: Fennel - Mint Wrapped Soap Bar 4oz | I22: FA2022001-4W | J22: 11 | K22: =J22/2 -> 5.5
A23: Balsam & Lavender Unwrapped Soap Bar 24oz | B23: FA2002006-24U | C23: 52 | D23: =C23/2 -> 26 | H23: Soap Ends | I23: SKU | J23: SRP | K23: Unit | L23: Qty | M23: Total
A24: Mud & Roses Unwrapped Soap Bar 1oz | B24: FA2011001-1U | C24: 4 | D24: =C24/2 -> 2 | H24: Handmade Soap Ends 1.5 pounds / 24oz | I24: FA2000005-24 | J24: 42 | K24: 21 | O24: Hunter’s Bro’ Soap & Shampoo Bar 4oz | P24: FA2000001-4W | Q24: 11 | R24: =Q24/2 -> 5.5
A25: Mud & Roses Unwrapped Soap Bar 4oz | B25: FA2011002-4U | C25: 10 | D25: =C25/2 -> 5 | H25: Wash Cloth | I25: SKU | J25: SRP | K25: Unit | L25: Qty | M25: Total
A26: Mud & Roses Wrapped Soap Bar 4oz | B26: FA2011003-4W | C26: 11 | D26: =C26/2 -> 5.5 | H26: Organic Washcloth - Cream | I26: FA9000024 | J26: 7 | K26: =J26/2 -> 3.5
A27: Mud & Roses Boxed Soap Bar 16oz | B27: FA2011004-16B | C27: 37 | D27: =C27/2 -> 18.5 | H27: Organic Washcloth - Vicuna | I27: FA9000002 | J27: 7 | K27: =J27/2 -> 3.5 | O27: Pink Camo Unscented Soap & Shampoo Bar 4oz | P27: FA2000002-4W | Q27: 11 | R27: =Q27/2 -> 5.5
A28: Mud & Roses Unwrapped Soap Bar 24oz | B28: FA2011005-24U | C28: 52 | D28: =C28/2 -> 26 | H28: Organic Washcloth - Sage | I28: FA9000003 | J28: 7 | K28: =J28/2 -> 3.5
A29: Marigold Unwrapped Soap Bar 1oz | B29: FA2010001-1U | C29: 4 | D29: =C29/2 -> 2 | H29: Hand Cream & Body Lotion/Wash | I29: SKU | J29: SRP | K29: Unit | L29: Qty | M29: Total
A30: Marigold Unwrapped Soap Bar 4oz | B30: FA2010002-4U | C30: 10 | D30: =C30/2 -> 5 | H30: Balsam & Cedar Hand Cream 2.3oz | I30: FA4001001-2.3 | J30: 22 | K30: =J30/2 -> 11 | O30: Hair Care | P30: SKU | Q30: SRP | R30: Unit | S30: Qty | T30: Total
A31: Marigold Wrapped Soap Bar 4oz | B31: FA2010003-4W | C31: 11 | D31: =C31/2 -> 5.5 | H31: Balsam & Cedar Body Lotion 8oz | I31: FA4001002-8 | J31: 33 | K31: =J31/2 -> 16.5 | O31: Lavender Balsam Shampoo Bar | P31: FA5002001-2.5B | Q31: 16 | R31: 8
A32: Marigold Boxed Soap Bar 16oz | B32: FA2010004-16B | C32: 37 | D32: =C32/2 -> 18.5 | H32: Balsam & Lavender Body Lotion 8oz | I32: FA4002002-8 | J32: 33 | K32: =J32/2 -> 16.5 | O32: Lilac Shampoo Bar 2.5oz | P32: FA5016001-2.5B | Q32: 16 | R32: 8
A33: Marigold Unwrapped Soap Bar 24oz | B33: FA2010005-24U | C33: 52 | D33: =C33/2 -> 26 | H33: Balsam & Lavender Body Wash 8oz | I33: FA4002004-8 | J33: 33 | K33: =J33/2 -> 16.5 | O33: Mountain Air Shampoo Bar 2.5oz | P33: FA5016001-2.5B | Q33: 16 | R33: =Q33/2 -> 8
A34: Chaga Mushroom Unwrapped Soap Bar 1oz | B34: FA2009001-1U | C34: 4 | D34: =C34/2 -> 2 | H34: Balsam & Cedar Body Wash 8oz | I34: FA4001005-9 | J34: 33 | K34: 16.5
A35: Chaga Mushroom Unwrapped Soap Bar 4oz | B35: FA2009002-4U | C35: 10 | D35: =C35/2 -> 5 | H35: Balsam & Lavender Hand Cream 2.3oz | I35: FA4002005-2.3 | J35: 22 | K35: 11
A36: Chaga Mushroom Wrapped Soap Bar 4oz | B36: FA2009003-4W | C36: 11 | D36: =C36/2 -> 5.5 | H36: Balsam & Lavender Hand Cream 4oz | I36: FA4002006-4 | J36: 28 | K36: 14 | O36: Shinrin Yoku Shampoo Bar 2.5oz | P36: FA5017001-2.5B | Q36: 16 | R36: =Q36/2 -> 8
A37: Chaga Mushroom Boxed Soap Bar 16oz | B37: FA2009004-16B | C37: 37 | D37: =C37/2 -> 18.5 | H37: Fennel - Mint Hand Lotion 8oz | I37: FA4022002-8 | J37: 33 | K37: =J37/2 -> 16.5
A38: Chaga Mushroom Unwrapped Soap Bar 24oz | B38: FA2009005-24U | C38: 52 | D38: =C38/2 -> 26 | H38: Fennel - Mint Hand Soap 8oz | I38: FA4022001-8 | J38: 33 | K38: =J38/2 -> 16.5
A39: Cranberry & Rose Unwrapped Soap Bar 1oz | B39: FA2007006-1U | C39: 4 | D39: =C39/2 -> 2 | H39: Lilac Body Lotion 8oz | I39: FA4015001-8 | J39: 33 | K39: 16.5 | O39: Chaga Wildflower Shampoo Bar 2.5oz | P39: FA5009001-2.5 | Q39: 16 | R39: =Q39/2 -> 8
A40: Cranberry & Rose Unwrapped Soap Bar 4oz | B40: FA2007002-4U | C40: 10 | D40: =C40/2 -> 5 | H40: Lip Balm | I40: SKU | J40: SRP | K40: Unit | L40: Qty | M40: Total
...

Sheet Project Schedule Phase 1 Old
A1: S | B1: Stormbreaker
A2: Enter Company Name in cell B2. | B2: Project Name | C2: Storm Breaker
A3: Enter the name of the Project Lead in cell B3. Enter the Project Start date in cell E3. Pooject Start: label is in cell C3. | D3: Project Start: | H3: Project Start: | J3: 44221
A4: The Display Week in cell E4 represents the starting week to display in the project schedule in cell I4. The project start date is considered Week 1. To change the display week, simply enter a new week number in cell E4. The starting date for each week, starting with the display week from cell E4, starts in cell I4 and is auto calculated. There are 8 weeks represented in this view from cell I4 through cell BF4. You should not modify these cells. Display Week: label is in cell C4. | D4: Display Week: | H4: Display Week: | J4: 1 | O4: =O5 -> 44221 | V4: =V5 -> 44228 | AC4: =AC5 -> 44235 | AJ4: =AJ5 -> 44242 | AQ4: =AQ5 -> 44249 | AX4: =AX5 -> 44256 | BE4: =BE5 -> 44263 | BL4: =BL5 -> 44270 | BS4: =BS5 -> 44277 | BZ4: =BZ5 -> 44284 | CG4: =CG5 -> 44291 | CN4: =CN5 -> 44298 | CU4: =CU5 -> 44305 | DB4: =DB5 -> 44312 | DI4: =DI5 -> 44319 | DP4: =DP5 -> 44326 | DW4: =DW5 -> 44333 | ED4: =ED5 -> 44340 | EK4: =EK5 -> 44347 | ER4: =ER5 -> 44354 | EY4: =EY5 -> 44361 | FF4: =FF5 -> 44368 | FM4: =FM5 -> 44375 | FT4: =FT5 -> 44382 | GA4: =GA5 -> 44389 | GH4: =GH5 -> 44396 | GO4: =GO5 -> 44403 | GV4: =GV5 -> 44410 | HC4: =HC5 -> 44417 | HJ4: =HJ5 -> 44424 | HQ4: =HQ5 -> 44431
A5: Cells I5 through BL5 contain the day number for the week represented in the cell block above each date cell and are auto calculated. You should not modify these cells. Today's date is outlined in Red (hex #AD3815) from today's date in row 5 through the entire date column to the end of the project schedule. | O5: =Project_Start-WEEKDAY(Project_Start,1)+2+7*(Display_Week-1) -> 44221 | P5: =O5+1 -> 44222 | Q5: =P5+1 -> 44223 | R5: =Q5+1 -> 44224 | S5: =R5+1 -> 44225 | T5: =S5+1 -> 44226 | U5: =T5+1 -> 44227 | V5: =U5+1 -> 44228 | W5: =V5+1 -> 44229 | ... HW5: =HV5+1 -> 44437
A6: This row contains headers for the project schedule that follows below them. Navigate from B6 through BL 6 to hear the content. The first letter of each day of the week for the date above that heading, starts in cell I6 and continues through cell BL6. All project timeline charting is auto generated based on the start and end dates entered, using conditional formats. Do not modify content in cells within columns after column I starting with cell I7. | B6: TASK | C6: Task ID | D6: ASSIGNED TO | E6: Hours Budgeted | F6: Hours Actual | G6: % of Budget | H6: PROGRESS | I6: Planned START | J6: Planned END | K6: Actual START | L6: Actual END | N6: DAYS | O6: =LEFT(TEXT(O5,"ddd"),1) -> M | P6: =LEFT(TEXT(P5,"ddd"),1) -> T | Q6: =LEFT(TEXT(Q5,"ddd"),1) -> W | R6: =LEFT(TEXT(R5,"ddd"),1) -> T | S6: =LEFT(TEXT(S5,"ddd"),1) -> F | T6: =LEFT(TEXT(T5,"ddd"),1) -> S | U6: =LEFT(TEXT(U5,"ddd"),1) -> S | V6: =LEFT(TEXT(V5,"ddd"),1) -> M | ... HW6: =LEFT(TEXT(HW5,"ddd"),1) -> S
A7: Do not delete this row. This row is hidden to preserve a formula that is used to highlight the curren day within the project schedule. | N7: =IF(OR(ISBLANK(task_start),ISBLANK(task_end)),"",task_end-task_start+1)
A8: Cell B8 contains the Phase 1 sample title. Enter a new Title in cell B8. Enter a name to assign the phase to, if it applies for your project, in cell C8. Enter Progress for the entire phase, if it applies for your project, in cell D8. Enter the start and end dates for the entire phase, if it applies for your project, in cells E8 and F8. The Gantt chart will automatically fill in the appropriate dates and shade according to the progress entered. To delete the phase and work only from tasks, simply delete this row. | B8: Phase 1 Alpha (UI Demo) | C8: Phase 1 Alpha (UI Demo) | E8: =SUM(E9:E22) -> 796 | F8: =SUM(F9:F22) -> #REF! | G8: =SUM(F9:F22)/SUM(E9:E22) -> #REF! | H8: =SUMPRODUCT(H9:H22,E9:E22)/E8 -> 1 | I8: 44151 | J8: 44188 | K8: 44151 | L8: 44204 | N8: =IF(OR(ISBLANK(task_start),ISBLANK(task_end)),"",task_end-task_start+1) -> 54
A9: Cell B9 contains the sample task "Task 1." Enter a new task name in cell B9. Enter a person to assign the task to in cell C9. Enter progres of the task in cell D9. A progress bar appears in the cell and is shaded according to the number in the cell. For example, 50 percent progress would shade half of the cell. Enter task start date in cell E9. Enter task end date in cell F9. A status bar shaded for the dates entered appears in blocks starting from cell I9 through BL9. | B9: Planning | C9: Alpha - Planning | D9: BiTS-DEV | E9: 100 | F9: =SUMIF(#REF!,'Project Schedule Phase 1 Old'!C9,#REF!) -> #REF! | G9: =F9/E9 -> #REF! | H9: 1 | I9: =Project_Start -> 44221 | J9: =I9+8 -> 44229 | K9: =Project_Start -> 44221 | L9: =K9+15 -> 44236 | N9: =IF(OR(ISBLANK(task_start),ISBLANK(task_end)),"",task_end-task_start+1) -> 16
A10: Rows 10 through 13 repeat the pattern from row 9. Repeat the instructions from cell A9 for all task rows in this worksheet. Overwrite any sample data. A sample of another phase starts in cell A14. Continue entering tasks in cells A10 through A13 or go to cell A14 to learn more. | B10: Web Application setup / continuous integration / User Rights | C10: Alpha - App Shell | D10: BiTS-DEV | E10: 160 | F10: =SUMIF(#REF!,'Project Schedule Phase 1 Old'!C10,#REF!) -> #REF! | G10: =F10/E10 -> #REF! | H10: 1 | I10: =Project_Start -> 44221 | J10: 44169 | K10: 44151 | L10: 44176 | N10: =IF(OR(ISBLANK(task_start),ISBLANK(task_end)),"",task_end-task_start+1) -> 26
B11: Landing Page Energy Modeling | C11: Alpha - Landing Page | D11: BiTS-DEV | E11: 80 | F11: =SUMIF(#REF!,'Project Schedule Phase 1 Old'!C11,#REF!) -> #REF! | G11: =F11/E11 -> #REF! | H11: 1 | I11: =Project_Start+7 -> 44228 | J11: 44169 | K11: #REF! | L11: 44176 | N11: =IF(OR(ISBLANK(task_start),ISBLANK(task_end)),"",task_end-task_start+1) -> #REF!
B12: Implement and maintain unit testing throughout all app components to ensure it is client facing | C12: Alpha - Unit Testing | D12: BiTS-DEV | E12: 40 | F12: =SUMIF(#REF!,'Project Schedule Phase 1 Old'!C12,#REF!) -> #REF! | G12: =F12/E12 -> #REF! | H12: 1 | I12: =Project_Start+7 -> 44228 | J12: 44162 | K12: #REF! | L12: 44195
B13: Configure system using a site layout graphic | C13: Alpha - Site Layout | D13: BiTS-DEV | E13: 60 | F13: =SUMIF(#REF!,'Project Schedule Phase 1 Old'!C13,#REF!) -> #REF! | G13: =F13/E13 -> #REF! | H13: 1 | I13: =J11+3-7 -> 44165 | J13: =I13+11+7 -> 44183 | K13: 44168 | L13: 44204
B14: Step Form: Selection of the primary and any secondary and tertiary Use Cases from a drop-down menu | C14: Alpha - Use Case Selection | D14: BiTS-DEV | E14: 80 | F14: =SUMIF(#REF!,'Project Schedule Phase 1 Old'!C14,#REF!) -> #REF! | G14: =F14/E14 -> #REF! | H14: 1 | I14: =$J$11+3 -> 44172 | J14: =I14+11 -> 44183 | K14: 44166 | L14: 44199
B15: Export to PDF model outputs + Data Files | C15: Alpha - Reporting | D15: BiTS-DEV | E15: 20 | F15: =SUMIF(#REF!,'Project Schedule Phase 1 Old'!C15,#REF!) -> #REF! | G15: =F15/E15 -> #REF! | H15: 1 | I15: =$J$11+10 -> 44179 | J15: =I15+4 -> 44183 | K15: =$J$11+10 -> 44179 | L15: 44195
B16: Product Data - Management aspect | C16: Alpha - Product Data | D16: BiTS-DEV | E16: 20 | F16: =SUMIF(#REF!,'Project Schedule Phase 1 Old'!C16,#REF!) -> #REF! | G16: =F16/E16 -> #REF! | H16: 1 | I16: =$J$11+10 -> 44179 | J16: =I16+4 -> 44183 | K16: =$J$11+10 -> 44179 | L16: =K16+4 -> 44183
B17: Importing capabilities from PVsyst- Import data files-.csv or excel, API integration with Helioscope | C17: Alpha - Importing | D17: BiTS-DEV | E17: 16 | F17: =SUMIF(#REF!,'Project Schedule Phase 1 Old'!C17,#REF!) -> #REF! | G17: =F17/E17 -> #REF! | H17: 1 | I17: =$J$11+10 -> 44179 | J17: =I17+4 -> 44183 | K17: 44179 | L17: =K17+4 -> 44183
B18: Data quality/verification step prior to model execution | C18: Alpha - Data Quality | D18: BiTS-DEV | E18: 20 | F18: =SUMIF(#REF!,'Project Schedule Phase 1 Old'!C18,#REF!) -> #REF! | G18: =F18/E18 -> #REF! | H18: 1 | I18: =J17+2 -> 44185 | J18: =I18+5 -> 44190 | K18: =L17+2 -> 44185 | L18: 44204
B19: Energy Model - Augmentation curves to be modelled and added as a next step to the model | C19: Alpha - Energy Model - Augmentation | D19: Ajinkya | E19: 60 | F19: =SUMIF(#REF!,'Project Schedule Phase 1 Old'!C19,#REF!) -> #REF! | G19: =F19/E19 -> #REF! | H19: 1 | I19: 44158 | J19: =I19+14 -> 44172 | K19: 44158 | L19: 44188
B20: Energy Model - Data quality checks for the excel sheet imported into the model for PV generation | C20: Alpha - Energy Model - Model Side Data Quality Checks | D20: Ajinkya / Rita | E20: 40 | F20: =SUMIF(#REF!,'Project Schedule Phase 1 Old'!C20,#REF!) -> #REF! | G20: =F20/E20 -> #REF! | H20: 1 | I20: =J19+1 -> 44173 | J20: =I20+7 -> 44180 | K20: =L19+1 -> 44189 | L20: 44204
B21: Energy Model - More Advanced Reports | C21: Alpha - Energy Model - Advanced Report | D21: Ajinkya / Rita | E21: 60 | F21: =SUMIF(#REF!,'Project Schedule Phase 1 Old'!C21,#REF!) -> #REF! | G21: =F21/E21 -> #REF! | H21: 1 | I21: 44179 | J21: =I21+12 -> 44191 | K21: 44179 | L21: 44204 | N21: =IF(OR(ISBLANK(task_start),ISBLANK(task_end)),"",task_end-task_start+1) -> 26
B22: Energy Model - Function to export PDF reports from the Model | C22: Alpha - Energy Model - PDF Report | D22: Ajinkya | E22: 40 | F22: =SUMIF(#REF!,'Project Schedule Phase 1 Old'!C22,#REF!) -> #REF! | G22: =F22/E22 -> #REF! | H22: 1 | I22: 44158 | J22: =I22+30 -> 44188 | K22: 44158 | L22: 44204
A23: The cell at right contains the Phase 2 sample title. You can create a new phase at any time within column B. This project schedule does not require phases. To remove the phase, simply delete the row. To create a new phase block in this row, enter a new Title in cell at right. To continue adding tasks to the phase above, enter a new row above this one and fill in the task data as in cell A9's instruction. Update the Phase details in cell at right based on cell A8's instruction. Continue navigating down column A cells to learn more. If you haven't added any new rows in this worksheet, you will find 2 additional sample phase blocks have been created for you in cells B20 and B26. Otherwise, navigate through column A cells to find the additional blocks. Repeat the instructions from cells A8 and A9 whenever you need to. | B23: NSOP Phase 1 Features Complete | C23: Phase 1 | D23: BiTS-DEV | E23: =SUM(E24:E44) -> 3173.8929 | F23: =SUM(F24:F44) -> #REF! | G23: =IFERROR(F23/E23,"") | H23: 0 | I23: 44221 | J23: 44372 | N23: =IF(OR(ISBLANK(task_start),ISBLANK(task_end)),"",task_end-task_start+1)
B24: Planning | C24: Fine Tune and Debug - Login Page UI Updates | D24: BiTS-DEV | E24: 5 | F24: =SUMIF(#REF!,'Project Schedule Phase 1 Old'!C24,#REF!) -> #REF! | G24: =IFERROR(F24/E24,"") | H24: 1 | I24: 44221 | J24: =I24+6+7 -> 44234 | K24: 44221 | L24: =K24+4 -> 44225 | N24: =IF(OR(ISBLANK(task_start),ISBLANK(task_end)),"",task_end-task_start+1) -> 5
B25: Fine Tuning / Clean up /Debug UI | C25: Fine Tune and Debug - Filters for Project List | D25: BiTS-DEV | E25: 10 | F25: =SUMIF(#REF!,'Project Schedule Phase 1 Old'!C25,#REF!) -> #REF! | G25: =IFERROR(F25/E25,"") | H25: 0.65 | I25: 44221 | J25: =I25+6+7 -> 44234 | K25: 44221 | L25: =K25+4 -> 44225
B26: Energy Model - Addition of additional battery manufacturers | C26: Fine Tune and Debug - Project View UI Updates | D26: BiTS-DEV | E26: 12.5 | F26: =SUMIF(#REF!,'Project Schedule Phase 1 Old'!C26,#REF!) -> #REF! | G26: =IFERROR(F26/E26,"") | H26: 0 | I26: 44221 | J26: =I26+6+7 -> 44234 | K26: 44225 | N26: =IF(OR(ISBLANK(task_start),ISBLANK(task_end)),"",task_end-task_start+1)
B27: Energy Model - More Advanced Reports | C27: Fine Tune and Debug - Variant Form Standardization (Simplification of Step Form Code Task) | D27: BiTS-DEV | E27: 10 | F27: =SUMIF(#REF!,'Project Schedule Phase 1 Old'!C27,#REF!) -> #REF! | G27: =IFERROR(F27/E27,"") | H27: 1 | I27: 44221 | J27: =I27+6+7 -> 44234 | K27: 44221 | L27: =K27+3 -> 44224 | N27: =IF(OR(ISBLANK(task_start),ISBLANK(task_end)),"",task_end-task_start+1) -> 4
C28: Fine Tune and Debug - Continuous Improvement | D28: BiTS-DEV | E28: =8*(J28-I28)/7 -> 172.57143 | F28: =SUMIF(#REF!,'Project Schedule Phase 1 Old'!C28,#REF!) -> #REF! | G28: =IFERROR(F28/E28,"") | H28: 0.05 | I28: 44221 | J28: =J23 -> 44372 | K28: 44221
C29: Isometeric view - Optimal Placement Algo | D29: Ajinkya or BiTS-DEV | E29: 250 | F29: =SUMIF(#REF!,'Project Schedule Phase 1 Old'!C29,#REF!) -> #REF! | G29: =IFERROR(F29/E29,"") | H29: 0 | I29: 44221 | J29: 44316
C30: Isometeric View - 2D Editor / Viewer | D30: BiTS-DEV | E30: 625 | F30: =SUMIF(#REF!,'Project Schedule Phase 1 Old'!C30,#REF!) -> #REF! | G30: =IFERROR(F30/E30,"") | H30: 0 | I30: 44235 | J30: 44337
C31: Isometric View - 3D Renders | D31: BiTS-DEV | E31: 1250 | F31: =SUMIF(#REF!,'Project Schedule Phase 1 Old'!C31,#REF!) -> #REF! | G31: =IFERROR(F31/E31,"") | H31: 0 | I31: 44263 | J31: 44372
B32: Isometeric view of the system - Intergration of sketchup or a similar API to create visuals but needs to be stored in a dataset for specific projects | C32: Help Section - FrontEnd | D32: BiTS-DEV | E32: 40 | F32: =SUMIF(#REF!,'Project Schedule Phase 1 Old'!C32,#REF!) -> #REF! | G32: =IFERROR(F32/E32,"") | H32: 0.35 | I32: 44228 | J32: =I32+6+7 -> 44241
B33: Help Section w/ Definitions | C33: Client Feedback Form | D33: BiTS-DEV | E33: 10 | F33: =SUMIF(#REF!,'Project Schedule Phase 1 Old'!C33,#REF!) -> #REF! | G33: =IFERROR(F33/E33,"") | H33: 0 | I33: 44228 | J33: =I33+6+7 -> 44241
B34: User feedback | C34: Admin Portal - Client List, Create, Edit, View + Add User | D34: BiTS-DEV | E34: 42.5 | F34: =SUMIF(#REF!,'Project Schedule Phase 1 Old'!C34,#REF!) -> #REF! | G34: =IFERROR(F34/E34,"") | H34: 0 | I34: 44228 | J34: 44248
B35: Web Application setup / continuous integration / User Rights | C35: Admin Portal - Client Dashboard (Show Projects / Users / Subscriptions) | D35: BiTS-DEV | E35: 40 | F35: =SUMIF(#REF!,'Project Schedule Phase 1 Old'!C35,#REF!) -> #REF! | G35: =IFERROR(F35/E35,"") | H35: 0 | I35: 44249 | J35: =I35+5+7 -> 44261
C36: Admin Portal - Client / User Invite Logic Flow | D36: BiTS-DEV | E36: 30 | F36: =SUMIF(#REF!,'Project Schedule Phase 1 Old'!C36,#REF!) -> #REF! | G36: =IFERROR(F36/E36,"") | H36: 0 | I36: 44249 | J36: =I36+5+7 -> 44261
C37: Admin Portal - User List, Create / Invite, Edit, View | D37: BiTS-DEV | E37: 22.5 | F37: =SUMIF(#REF!,'Project Schedule Phase 1 Old'!C37,#REF!) -> #REF! | G37: =IFERROR(F37/E37,"") | H37: 0 | I37: 44249 | J37: =I37+5+7 -> 44261
C38: Admin Portal - Client Feedback Management Page | D38: BiTS-DEV | E38: 10 | F38: =SUMIF(#REF!,'Project Schedule Phase 1 Old'!C38,#REF!) -> #REF! | G38: =IFERROR(F38/E38,"") | H38: 0 | I38: 44249 | J38: =I38+5+7 -> 44261
C39: Admin Portal - Subscription Logic / Configuration | D39: BiTS-DEV | E39: 20 | F39: =SUMIF(#REF!,'Project Schedule Phase 1 Old'!C39,#REF!) -> #REF! | G39: =IFERROR(F39/E39,"") | H39: 0 | I39: 44249 | J39: =I39+5+7 -> 44261
C40: Model - Continuous Improvement and Debug | D40: Ajinkya | E40: =8*(J40-I40)/7 -> 172.57143 | F40: =SUMIF(#REF!,'Project Schedule Phase 1 Old'!C40,#REF!) -> #REF! | G40: =IFERROR(F40/E40,"") | H40: 0 | I40: 44221 | J40: =J23 -> 44372
...

Sheet 2021WK11 Sprint Summary
A1: Phase 1 | B1: WK09 Actual | C1: WK010 Plan | D1: WK10 Actual | E1: WK11 Plan
A2: Fine Tune and Debug - Login Page UI Updates | B2: 1 | C2: 1 | D2: 1 | E2: 1
A3: Fine Tune and Debug - Filters for Project List | B3: 1 | C3: 1 | D3: 1 | E3: 1
A4: Fine Tune and Debug - Project View UI Updates | B4: 0 | C4: 1 | D4: 0.3 | E4: 0.5
A5: Fine Tune and Debug - Variant Form Standardization (Simplification of Step Form Code Task) | B5: 1 | C5: 1 | D5: 1 | E5: 1
A6: Fine Tune and Debug - Continuous Improvement | B6: 0.15 | C6: 0.15 | D6: 0.15 | E6: 0.15
A7: Isometeric view - Optimal Placement Algo / Block Creation | B7: 0 | C7: 0 | D7: 0 | E7: 0
A8: Isometeric View - 2D Editor | B8: 0 | C8: 0 | D8: 0.05 | E8: 0.1
A9: Isometric View - 3D Rendering | B9: 0 | C9: 0 | D9: 0 | E9: 0
A10: Help Section - FrontEnd | B10: 1 | C10: 1 | D10: 1 | E10: 1
A11: Client Feedback Form | B11: 0.5 | C11: 1 | D11: 0.5 | E11: 0.5
A12: Admin Portal - Client List, Create, Edit, View + Add User | B12: 0 | C12: 1 | D12: 1 | E12: 1
A13: Admin Portal - Client Dashboard (Show Projects / Users / Subscriptions) | B13: 0 | C13: 0 | D13: 0 | E13: 0
... A24: Demonstration to customer (Demo Data) | B24: 0 | C24: 0 | D24: 0 | E24: 0

Sheet 2021WK10 Sprint Summary
A1: Phase 1 | B1: WK09 Actual | C1: WK010 Plan | D1: WK10 Actual | E1: WK11 Plan
A2: Fine Tune and Debug - Login Page UI Updates | B2: 1 | C2: 1 | D2: 1 | E2: 1
A3: Fine Tune and Debug - Filters for Project List | B3: 1 | C3: 1 | D3: 1 | E3: 1
A4: Fine Tune and Debug - Project View UI Updates | B4: 0 | C4: 1 | D4: 0 | E4: 1
A5: Fine Tune and Debug - Variant Form Standardization (Simplification of Step Form Code Task) | B5: 1 | C5: 1 | D5: 1 | E5: 1
A6: Fine Tune and Debug - Continuous Improvement | B6: 0.15 | C6: 0.15 | D6: 0.15 | E6: 0.15
A7: Isometeric view - Optimal Placement Algo | B7: 0 | C7: 0 | D7: 0 | E7: 0
A8: Isometeric View - 2D Editor | B8: 0 | C8: 0 | D8: 0 | E8: 0
A9: Isometric View - 3D Rendering | B9: 0 | C9: 0 | D9: 0 | E9: 0
A10: Help Section - FrontEnd | B10: 1 | C10: 1 | D10: 1 | E10: 1
A11: Client Feedback Form | B11: 0.5 | C11: 1 | D11: 0.5 | E11: 1
A12: Admin Portal - Client List, Create, Edit, View + Add User | B12: 0 | C12: 0.1 | D12: 0 | E12: 1
A13: Admin Portal - Client Dashboard (Show Projects / Users / Subscriptions) | B13: 0 | C13: 0 | D13: 0 | E13: 0
... A19: State of Charge Model Feature | B19: 1 | C19: 1 | D19: 1 | E19: 1
A20: Use Case Model Features | B20: 0 | C20: 0 | D20: 0 | E20: 0 | F20: Plan
A21: Help Section - Content | B21: 0.35 | C21: 0.3 | D21: 0.4 | E21: 0.6 | F21: 80
A22: Add Battery Manufacturers | B22: 0.8 | C22: 0.8 | D22: 0.8 | E22: 0.85 | F22: 100
A23: Add Page to the CEA website | B23: 0 | C23: 0 | D23: 0 | E23: 0.3 | F23: 70
A24: Demonstration to customer (Demo Data) | B24: 0 | C24: 0 | D24: 0 | E24: 0

Sheet 2021WK09 Sprint Summary
A1: Phase 1 | B1: WK08 Actual | C1: WK09 Plan | D1: WK09 Actual | E1: WK09 Plan | H1: WK09 Actual | I1: WK10 Plan
A2: Fine Tune and Debug - Login Page UI Updates | B2: 1 | C2: 1 | D2: 1 | E2: 1
A3: Fine Tune and Debug - Filters for Project List | B3: 1 | C3: 1 | D3: 1 | E3: 1
A4: Fine Tune and Debug - Project View UI Updates | B4: 0 | C4: 0 | D4: 0 | E4: 1
A5: Fine Tune and Debug - Variant Form Standardization (Simplification of Step Form Code Task) | B5: 1 | C5: 1 | D5: 1 | E5: 1
A6: Fine Tune and Debug - Continuous Improvement | B6: 0.1 | C6: 0.15 | D6: 0.15 | E6: 0.15
A7: Isometeric view - Optimal Placement Algo | B7: 0 | C7: 0 | D7: 0 | E7: 0
A8: Isometeric View - 2D Editor | B8: 0 | C8: 0 | D8: 0 | E8: 0
A9: Isometric View - 3D Rendering | B9: 0 | C9: 0 | D9: 0 | E9: 0
A10: Help Section - FrontEnd | B10: 0.95 | C10: 1 | D10: 1 | E10: 1
A11: Client Feedback Form | B11: 0 | C11: 1 | D11: 0.5 | E11: 1
A12: Admin Portal - Client List, Create, Edit, View + Add User | B12: 0 | C12: 0.05 | D12: 0 | E12: 0.1
A13: Admin Portal - Client Dashboard (Show Projects / Users / Subscriptions) | B13: 0 | C13: 0 | D13: 0 | E13: 0
... A24: Demonstration to customer (Demo Data) | B24: 0 | C24: 0 | D24: 0 | E24: 0

Sheet 2021WK08 Sprint Summary
A1: Phase 1 | B1: WK07 Actual | C1: WK08 Plan | D1: WK08 Actual | E1: WK09 Plan | H1: WK09 Actual | I1: WK10 Plan
A2: Fine Tune and Debug - Login Page UI Updates | B2: 1 | C2: 1 | D2: 1 | E2: 1
A3: Fine Tune and Debug - Filters for Project List | B3: 1 | C3: 1 | D3: 1 | E3: 1
A4: Fine Tune and Debug - Project View UI Updates | B4: 0 | C4: 0 | D4: 0 | E4: 0
A5: Fine Tune and Debug - Variant Form Standardization (Simplification of Step Form Code Task) | B5: 1 | C5: 1 | D5: 1 | E5: 1
A6: Fine Tune and Debug - Continuous Improvement | B6: 0.1 | C6: 0.15 | D6: 0.1 | E6: 0.15
A7: Isometeric view - Optimal Placement Algo | B7: 0 | C7: 0 | D7: 0 | E7: 0
A8: Isometeric View - 2D Editor | B8: 0 | C8: 0 | D8: 0 | E8: 0
A9: Isometric View - 3D Rendering | B9: 0 | C9: 0 | D9: 0 | E9: 0
A10: Help Section - FrontEnd | B10: 0.7 | C10: 1 | D10: 0.95 | E10: 1
A11: Client Feedback Form | B11: 0 | C11: 1 | D11: 0 | E11: 1
A12: Admin Portal - Client List, Create, Edit, View + Add User | B12: 0 | C12: 0 | D12: 0 | E12: 0.05
A13: Admin Portal - Client Dashboard (Show Projects / Users / Subscriptions) | B13: 0 | C13: 0 | D13: 0 | E13: 0
... A24: Demonstration to customer (Demo Data) | B24: 0 | C24: 0 | D24: 0 | E24: 0

Sheet 2021WK06 Sprint Summary
A1: Phase 1 | B1: WK05 Actual | C1: WK06 Plan | D1: WK06 Actual | E1: WK07 Plan
A2: Fine Tune and Debug - Login Page UI Updates | B2: 1 | C2: 1 | D2: 1 | E2: 1
A3: Fine Tune and Debug - Filters for Project List | B3: 1 | C3: 1 | D3: 1 | E3: 1
A4: Fine Tune and Debug - Project View UI Updates | B4: 0 | C4: 1 | D4: 0 | E4: 0
A5: Fine Tune and Debug - Variant Form Standardization (Simplification of Step Form Code Task) | B5: 1 | C5: 1 | D5: 1 | E5: 1
A6: Fine Tune and Debug - Continuous Improvement | B6: 0.1 | C6: 0.15 | D6: 0.1 | E6: 0.15
A7: Isometeric view - Optimal Placement Algo | B7: 0 | C7: 0 | D7: 0 | E7: 0
A8: Isometeric View - 2D Editor | B8: 0 | C8: 0 | D8: 0 | E8: 0
A9: Isometric View - 3D Rendering | B9: 0 | C9: 0 | D9: 0 | E9: 0
A10: Help Section - FrontEnd | B10: 0.35 | C10: 0.75 | D10: 0.5 | E10: 0.75
A11: Client Feedback Form | B11: 0 | C11: 0.5 | D11: 0 | E11: 0.5
A12: Admin Portal - Client List, Create, Edit, View + Add User | B12: 0 | C12: 0 | D12: 0 | E12: 0
A13: Admin Portal - Client Dashboard (Show Projects / Users / Subscriptions) | B13: 0 | C13: 0 | D13: 0 | E13: 0
... A24: Demonstration to customer (Demo Data) | B24: 0 | C24: 0 | D24: 0 | E24: 0

Sheet 2021WK05 Sprint Summary
A1: Phase 1 | B1: WK04 Actual | C1: WK05 Plan | D1: WK05 Actual | E1: WK06 Plan
A2: Fine Tune and Debug - Login Page UI Updates | B2: 1 | C2: 1 | D2: 1 | E2: 1
A3: Fine Tune and Debug - Filters for Project List | B3: 1 | C3: 1 | D3: 1 | E3: 1
A4: Fine Tune and Debug - Project View UI Updates | B4: 0 | C4: 1 | D4: 0 | E4: 1
A5: Fine Tune and Debug - Variant Form Standardization (Simplification of Step Form Code Task) | B5: 1 | C5: 1 | D5: 1 | E5: 1
A6: Fine Tune and Debug - Continuous Improvement | B6: 0.05 | C6: 0.1 | D6: 0.1 | E6: 0.15
A7: Isometeric view - Optimal Placement Algo | B7: 0 | C7: 0.02 | D7: 0 | E7: 0
A8: Isometeric View - 2D Editor | B8: 0 | C8: 0 | D8: 0 | E8: 0
A9: Isometric View - 3D Rendering | B9: 0 | C9: 0 | D9: 0 | E9: 0
A10: Help Section - FrontEnd | B10: 0 | C10: 0.5 | D10: 0.35 | E10: 0.75
A11: Client Feedback Form | B11: 0 | C11: 0.5 | D11: 0 | E11: 0.5
A12: Admin Portal - Client List, Create, Edit, View + Add User | B12: 0 | C12: 0 | D12: 0 | E12: 0
A13: Admin Portal - Client Dashboard (Show Projects / Users / Subscriptions) | B13: 0 | C13: 0 | D13: 0 | E13: 0
... A22: Demonstration to customer (Demo Data) | B22: 0 | C22: 0 | D22: 0 | E22: 0

Sheet 2021WK04 Sprint Summary
A1: Phase 1 | B1: WK03 Actual | C1: WK04 Plan | D1: WK04 Actual | E1: WK05 Plan
A2: Fine Tune and Debug - Login Page UI Updates | B2: 0 | C2: 1 | D2: 1 | E2: 1
A3: Fine Tune and Debug - Filters for Project List | B3: 0 | C3: 1 | D3: 1 | E3: 1
A4: Fine Tune and Debug - Project View UI Updates | B4: 0 | C4: 0 | D4: 0 | E4: 1
A5: Fine Tune and Debug - Variant Form Standardization (Simplification of Step Form Code Task) | B5: 0 | C5: 1 | D5: 1 | E5: 1
A6: Fine Tune and Debug - Continuous Improvement | B6: 0 | C6: 0.05 | D6: 0.05 | E6: 0.1
A7: Isometeric view - Optimal Placement Algo | B7: 0 | C7: 0 | D7: 0 | E7: 0.02
A8: Isometeric View - 2D Editor | B8: 0 | C8: 0 | D8: 0 | E8: 0
A9: Isometric View - 3D Rendering | B9: 0 | C9: 0 | D9: 0 | E9: 0
A10: Help Section - FrontEnd | B10: 0 | C10: 0 | D10: 0 | E10: 0.5
A11: Client Feedback Form | B11: 0 | C11: 0 | D11: 0 | E11: 0.5
A12: Admin Portal - Client List, Create, Edit, View + Add User | B12: 0 | C12: 0 | D12: 0 | E12: 0
A13: Admin Portal - Client Dashboard (Show Projects / Users / Subscriptions) | B13: 0 | C13: 0 | D13: 0 | E13: 0
... A22: Demonstration to customer (Demo Data) | B22: 0 | C22: 0 | D22: 0 | E22: 0

Sheet WK52 Sprint Summary
A1: Phase 1 Alpha (UI Demo) | B1: WK52 Actual | C1: WK202101 Plan | D1: WK202101 Actual | E1: 202102 Plan
A2: Planning | B2: 1 | C2: 1 | D2: 1 | E2: 1
A3: Web Application setup / continuous integration / User Rights | B3: 1 | C3: 1 | D3: 1 | E3: 1
A4: Landing Page Energy Modeling | B4: 1 | C4: 1 | D4: 1 | E4: 1
A5: Implement and maintain unit testing throughout all app components to ensure it is client facing | B5: 1 | C5: 1 | D5: 1 | E5: 1
A6: Configure system using a site layout graphic | B6: 0.8 | C6: 1 | D6: 1 | E6: 1
A7: Selection of the primary and any secondary and tertiary Use Cases from a drop-down menu | B7: 0.95 | C7: 1 | D7: 0.95 | E7: 1
A8: Export to PDF model outputs + Data Files | B8: 1 | C8: 1 | D8: 1 | E8: 1
A9: Product Data - Management aspect | B9: 1 | C9: 1 | D9: 1 | E9: 1
A10: Importing capabilities from PVsyst- Import data files-.csv or excel, API integration with Helioscope | B10: 1 | C10: 1 | D10: 1 | E10: 1
A11: Data quality/verification step prior to model execution | B11: 0.7 | C11: 1 | D11: 1 | E11: 1
A12: Energy Model - Augmentation curves to be modelled and added as a next step to the model | B12: 1 | C12: 1 | D12: 1 | E12: 1
A13: Energy Model - Data quality checks for the excel sheet imported into the model for PV generation | B13: 1 | C13: 1 | D13: 1 | E13: 1
A14: Energy Model - More Advanced Reports | B14: 0.2 | C14: 0.8 | D14: 1 | E14: 1
A15: Energy Model - Addition of additional battery manufacturers - MOVED TO JAN SPRINT
A16: Energy Model - Function to export PDF reports from the Model | B16: 1 | C16: 1 | D16: 1 | E16: 1

Sheet Alpha Work Breakdown
A1: Feature | B1: Details | C1: Alpha Version UI Est (Hours) | D1: Time Spent (Actual) (Hours) | E1: Remaining Work (Hours)
A2: Planning | B2: Project Planning | C2: 100 | D2: 50 | E2: =C2-D2 -> 50
A3: Landing Page | B3: Display of saved projects and their current status Ability to create new project Tutorial Quick Start Guide (Button) User profile details | C3: 80 | E3: =C3-D3 -> 80
A4: Implement and maintain unit testing throughout all app components to ensure it is client facing | B4: Lightweight Version in Alpha | C4: 40 | E4: =C4-D4 -> 40
A5: Configure system using a site layout graphic | B5: Storage Solar + Storage | C5: 60 | E5: =C5-D5 -> 60
A6: Selection of the primary and any secondary and tertiary Use Cases from a drop-down menu | B6: Alpha 1. Capacity firming 2. Arbitrage 3. User Defined Multiple form based fill in pages where user is expected to provide user inputs | C6: 80 | E6: =C6-D6 -> 80
A7: Export to PDF model outputs + Data Files | B7: Basic PDF Report | C7: 20 | E7: =C7-D7 -> 20
A8: Product Data - Management aspect | B8: Battery data from manufacturer for modelling View, Import (Client profile Specific) , Export, Delete (Client profile Specific) , Custom component to be added Visual Representation w/ Filter, Sort and pagination | C8: 20 | E8: =C8-D8 -> 20
A9: Importing capabilities from PVsyst- Import data files-.csv or excel, API integration with Helioscope | B9: Basic Importing capabilities from PVsyst Import data files .csv or excel. Visual representation of what has been uploaded (1 Data set can upload excel or csv) | C9: 16 | E9: =C9-D9 -> 16
A10: Data quality/verification step prior to model execution | B10: Back end data quality checks | C10: 20 | E10: =C10-D10 -> 20
A11: Web Application setup / continuous integration / User Rights | C11: 160 | D11: 55 | E11: =C11-D11 -> 105
B12: Total | C12: =SUM(C2:C11) -> 596 | D12: =SUM(D2:D11) -> 105 | E12: =SUM(E2:E11) -> 491
D13: Est Week Remaining | E13: =E12/120 -> 4.0916667
D14: Completion Date | E14: =NOW()+7*E13 -> 46127.144

Sheet WK50 Sprint Summary
A1: Phase 1 Alpha (UI Demo) | B1: WK49 Actual | C1: WK50 Plan | D1: Wk50 Actual | E1: Wk51 Plan
A2: Planning | B2: 1 | C2: 1 | D2: 1 | E2: 1
A3: Web Application setup / continuous integration / User Rights | B3: 1 | C3: 1 | D3: 1 | E3: 1
A4: Landing Page Energy Modeling | B4: 0.6 | C4: 1 | D4: 1 | E4: 1
A5: Implement and maintain unit testing throughout all app components to ensure it is client facing | B5: 0.8 | C5: 1 | D5: 0.8 | E5: 1
A6: Configure system using a site layout graphic | B6: 0 | C6: 0.2 | D6: 0.2 | E6: 1
A7: Selection of the primary and any secondary and tertiary Use Cases from a drop-down menu | B7: 0 | C7: 0.8 | D7: 0.5 | E7: 1
A8: Export to PDF model outputs + Data Files | B8: 0 | C8: 0 | D8: 0 | E8: 1
A9: Product Data - Management aspect | B9: 0 | C9: 0 | D9: 0 | E9: 0.2
A10: Importing capabilities from PVsyst- Import data files-.csv or excel, API integration with Helioscope | B10: 0 | C10: 0 | D10: 0 | E10: 1
A11: Data quality/verification step prior to model execution | B11: 0 | C11: 0 | D11: 0 | E11: 0.2
A12: Energy Model - Augmentation curves to be modelled and added as a next step to the model | B12: 0.4 | C12: 1 | D12: 0.4 | E12: 1
A13: Energy Model - Data quality checks for the excel sheet imported into the model for PV generation | B13: 0 | C13: 0 | D13: 0 | E13: 0
A14: Energy Model - More Advanced Reports | B14: 0 | C14: 0 | D14: 0 | E14: 0.5
A15: Energy Model - Addition of additional battery manufacturers - MOVED TO JAN SPRINT
A16: Energy Model - Function to export PDF reports from the Model | B16: 1 | C16: 1 | D16: 1 | E16: 1

Sheet WK49 Sprint Summary
A1: Phase 1 Alpha (UI Demo) | B1: WK48 Actual | C1: WK49 Plan | D1: Wk49 Actual | E1: Wk50 Plan
A2: Planning | B2: 0.8 | C2: 1 | D2: 1 | E2: 1
A3: Web Application setup / continuous integration / User Rights | B3: 0.8 | C3: 1 | D3: 1 | E3: 1
A4: Landing Page Energy Modeling | B4: 0 | C4: 1 | D4: 0.6 | E4: 1
A5: Implement and maintain unit testing throughout all app components to ensure it is client facing | B5: 0.7 | C5: 1 | D5: 0.8 | E5: 1
A6: Configure system using a site layout graphic | B6: 0 | C6: 0 | D6: 0 | E6: 0.2
A7: Selection of the primary and any secondary and tertiary Use Cases from a drop-down menu | B7: 0 | C7: 0 | D7: 0 | E7: 0.8
A8: Export to PDF model outputs + Data Files | B8: 0 | C8: 0 | D8: 0 | E8: 0
A9: Product Data - Management aspect | B9: 0 | C9: 0 | D9: 0 | E9: 0
A10: Importing capabilities from PVsyst- Import data files-.csv or excel, API integration with Helioscope | B10: 0 | C10: 0 | D10: 0 | E10: 0
A11: Data quality/verification step prior to model execution | B11: 0 | C11: 0 | D11: 0 | E11: 0
A12: Energy Model - Augmentation curves to be modelled and added as a next step to the model | B12: 0.1 | C12: 0.8 | D12: 0.4 | E12: 1
A13: Energy Model - Data quality checks for the excel sheet imported into the model for PV generation | B13: 0 | C13: 0 | D13: 0 | E13: 0
... A15: Energy Model - Function to export PDF reports from the Model | B15: 0.2 | C15: 0.2 | D15: 1 | E15: 1
